2016-04-26 13:08:02 [boto] ERROR: Caught exception reading instance data
Traceback (most recent call last):
  File "/Library/Python/2.7/site-packages/boto/utils.py", line 210, in retry_url
    r = opener.open(req, timeout=timeout)
  File "/System/Library/Frameworks/Python.framework/Versions/2.7/lib/python2.7/urllib2.py", line 404, in open
    response = self._open(req, data)
  File "/System/Library/Frameworks/Python.framework/Versions/2.7/lib/python2.7/urllib2.py", line 422, in _open
    '_open', req)
  File "/System/Library/Frameworks/Python.framework/Versions/2.7/lib/python2.7/urllib2.py", line 382, in _call_chain
    result = func(*args)
  File "/System/Library/Frameworks/Python.framework/Versions/2.7/lib/python2.7/urllib2.py", line 1214, in http_open
    return self.do_open(httplib.HTTPConnection, req)
  File "/System/Library/Frameworks/Python.framework/Versions/2.7/lib/python2.7/urllib2.py", line 1184, in do_open
    raise URLError(err)
URLError: <urlopen error timed out>
2016-04-26 13:08:02 [boto] ERROR: Unable to read instance data, giving up
